[2023-06-13T04:19:32.216+0000] {taskinstance.py:1103} INFO - Dependencies all met for dep_context=non-requeueable deps ti=<TaskInstance: vamosSigue.insert_data_from_file scheduled__2023-06-12T00:00:00+00:00 [queued]>
[2023-06-13T04:19:32.234+0000] {taskinstance.py:1103} INFO - Dependencies all met for dep_context=requeueable deps ti=<TaskInstance: vamosSigue.insert_data_from_file scheduled__2023-06-12T00:00:00+00:00 [queued]>
[2023-06-13T04:19:32.235+0000] {taskinstance.py:1308} INFO - Starting attempt 2 of 2
[2023-06-13T04:19:32.262+0000] {taskinstance.py:1327} INFO - Executing <Task(PythonOperator): insert_data_from_file> on 2023-06-12 00:00:00+00:00
[2023-06-13T04:19:32.270+0000] {standard_task_runner.py:57} INFO - Started process 1523 to run task
[2023-06-13T04:19:32.274+0000] {standard_task_runner.py:84} INFO - Running: ['***', 'tasks', 'run', 'vamosSigue', 'insert_data_from_file', 'scheduled__2023-06-12T00:00:00+00:00', '--job-id', '51', '--raw', '--subdir', 'DAGS_FOLDER/dbeaverFunciona.py', '--cfg-path', '/tmp/tmpoebbtc45']
[2023-06-13T04:19:32.275+0000] {standard_task_runner.py:85} INFO - Job 51: Subtask insert_data_from_file
[2023-06-13T04:19:32.362+0000] {task_command.py:410} INFO - Running <TaskInstance: vamosSigue.insert_data_from_file scheduled__2023-06-12T00:00:00+00:00 [running]> on host a26553e1bb12
[2023-06-13T04:19:32.498+0000] {taskinstance.py:1547} INFO - Exporting env vars: AIRFLOW_CTX_DAG_OWNER='***' AIRFLOW_CTX_DAG_ID='vamosSigue' AIRFLOW_CTX_TASK_ID='insert_data_from_file' AIRFLOW_CTX_EXECUTION_DATE='2023-06-12T00:00:00+00:00' AIRFLOW_CTX_TRY_NUMBER='2' AIRFLOW_CTX_DAG_RUN_ID='scheduled__2023-06-12T00:00:00+00:00'
[2023-06-13T04:19:32.499+0000] {taskinstance.py:1824} ERROR - Task failed with exception
Traceback (most recent call last):
  File "/home/airflow/.local/lib/python3.7/site-packages/airflow/operators/python.py", line 181, in execute
    return_value = self.execute_callable()
  File "/home/airflow/.local/lib/python3.7/site-packages/airflow/operators/python.py", line 198, in execute_callable
    return self.python_callable(*self.op_args, **self.op_kwargs)
  File "/opt/airflow/dags/dbeaverFunciona.py", line 8, in insert_data_from_file
    with open(r'\Users\hikik\repositorios\airdock\dags\file.csv','r') as file:
FileNotFoundError: [Errno 2] No such file or directory: '\\Users\\hikik\\repositorios\\airdock\\dags\\file.csv'
[2023-06-13T04:19:32.515+0000] {taskinstance.py:1350} INFO - Marking task as FAILED. dag_id=vamosSigue, task_id=insert_data_from_file, execution_date=20230612T000000, start_date=20230613T041932, end_date=20230613T041932
[2023-06-13T04:19:32.533+0000] {standard_task_runner.py:109} ERROR - Failed to execute job 51 for task insert_data_from_file ([Errno 2] No such file or directory: '\\Users\\hikik\\repositorios\\airdock\\dags\\file.csv'; 1523)
[2023-06-13T04:19:32.568+0000] {local_task_job_runner.py:225} INFO - Task exited with return code 1
[2023-06-13T04:19:32.595+0000] {taskinstance.py:2651} INFO - 0 downstream tasks scheduled from follow-on schedule check
