[2023-06-13T03:22:57.708+0000] {taskinstance.py:1103} INFO - Dependencies all met for dep_context=non-requeueable deps ti=<TaskInstance: vamosSigue.creacion_tabla scheduled__2023-06-12T00:00:00+00:00 [queued]>
[2023-06-13T03:22:57.729+0000] {taskinstance.py:1103} INFO - Dependencies all met for dep_context=requeueable deps ti=<TaskInstance: vamosSigue.creacion_tabla scheduled__2023-06-12T00:00:00+00:00 [queued]>
[2023-06-13T03:22:57.730+0000] {taskinstance.py:1308} INFO - Starting attempt 3 of 3
[2023-06-13T03:22:57.754+0000] {taskinstance.py:1327} INFO - Executing <Task(PostgresOperator): creacion_tabla> on 2023-06-12 00:00:00+00:00
[2023-06-13T03:22:57.762+0000] {standard_task_runner.py:57} INFO - Started process 570 to run task
[2023-06-13T03:22:57.765+0000] {standard_task_runner.py:84} INFO - Running: ['***', 'tasks', 'run', 'vamosSigue', 'creacion_tabla', 'scheduled__2023-06-12T00:00:00+00:00', '--job-id', '45', '--raw', '--subdir', 'DAGS_FOLDER/dbeaverFunciona.py', '--cfg-path', '/tmp/tmp1i_9ubx4']
[2023-06-13T03:22:57.766+0000] {standard_task_runner.py:85} INFO - Job 45: Subtask creacion_tabla
[2023-06-13T03:22:57.838+0000] {task_command.py:410} INFO - Running <TaskInstance: vamosSigue.creacion_tabla scheduled__2023-06-12T00:00:00+00:00 [running]> on host a26553e1bb12
[2023-06-13T03:22:57.963+0000] {taskinstance.py:1547} INFO - Exporting env vars: AIRFLOW_CTX_DAG_OWNER='***' AIRFLOW_CTX_DAG_ID='vamosSigue' AIRFLOW_CTX_TASK_ID='creacion_tabla' AIRFLOW_CTX_EXECUTION_DATE='2023-06-12T00:00:00+00:00' AIRFLOW_CTX_TRY_NUMBER='3' AIRFLOW_CTX_DAG_RUN_ID='scheduled__2023-06-12T00:00:00+00:00'
[2023-06-13T03:22:57.965+0000] {sql.py:262} INFO - Executing: 
            CREATE TABLE IF NOT EXISTS datos (
            id VARCHAR NOT NULL,
            country VARCHAR NOT NULL,
            )
          
[2023-06-13T03:22:57.978+0000] {base.py:73} INFO - Using connection ID 'postgres_localhost' for task execution.
[2023-06-13T03:22:58.079+0000] {base.py:73} INFO - Using connection ID 'postgres_localhost' for task execution.
[2023-06-13T03:22:58.101+0000] {sql.py:375} INFO - Running statement: 
            CREATE TABLE IF NOT EXISTS datos (
            id VARCHAR NOT NULL,
            country VARCHAR NOT NULL,
            )
          , parameters: None
[2023-06-13T03:22:58.109+0000] {taskinstance.py:1824} ERROR - Task failed with exception
Traceback (most recent call last):
  File "/home/airflow/.local/lib/python3.7/site-packages/airflow/providers/common/sql/operators/sql.py", line 274, in execute
    **extra_kwargs,
  File "/home/airflow/.local/lib/python3.7/site-packages/airflow/providers/common/sql/hooks/sql.py", line 349, in run
    self._run_command(cur, sql_statement, parameters)
  File "/home/airflow/.local/lib/python3.7/site-packages/airflow/providers/common/sql/hooks/sql.py", line 380, in _run_command
    cur.execute(sql_statement)
psycopg2.errors.SyntaxError: syntax error at or near ")"
LINE 5:             )
                    ^

[2023-06-13T03:22:58.127+0000] {taskinstance.py:1350} INFO - Marking task as FAILED. dag_id=vamosSigue, task_id=creacion_tabla, execution_date=20230612T000000, start_date=20230613T032257, end_date=20230613T032258
[2023-06-13T03:22:58.149+0000] {standard_task_runner.py:109} ERROR - Failed to execute job 45 for task creacion_tabla (syntax error at or near ")"
LINE 5:             )
                    ^
; 570)
[2023-06-13T03:22:58.179+0000] {local_task_job_runner.py:225} INFO - Task exited with return code 1
[2023-06-13T03:22:58.211+0000] {taskinstance.py:2651} INFO - 0 downstream tasks scheduled from follow-on schedule check
