[2023-06-13T03:17:33.949+0000] {taskinstance.py:1103} INFO - Dependencies all met for dep_context=non-requeueable deps ti=<TaskInstance: vamosSigue.creacion_tabla scheduled__2023-06-12T00:00:00+00:00 [queued]>
[2023-06-13T03:17:33.964+0000] {taskinstance.py:1103} INFO - Dependencies all met for dep_context=requeueable deps ti=<TaskInstance: vamosSigue.creacion_tabla scheduled__2023-06-12T00:00:00+00:00 [queued]>
[2023-06-13T03:17:33.965+0000] {taskinstance.py:1308} INFO - Starting attempt 1 of 1
[2023-06-13T03:17:33.987+0000] {taskinstance.py:1327} INFO - Executing <Task(PostgresOperator): creacion_tabla> on 2023-06-12 00:00:00+00:00
[2023-06-13T03:17:33.994+0000] {standard_task_runner.py:57} INFO - Started process 473 to run task
[2023-06-13T03:17:33.998+0000] {standard_task_runner.py:84} INFO - Running: ['***', 'tasks', 'run', 'vamosSigue', 'creacion_tabla', 'scheduled__2023-06-12T00:00:00+00:00', '--job-id', '42', '--raw', '--subdir', 'DAGS_FOLDER/dbeaverFunciona.py', '--cfg-path', '/tmp/tmpcnzrcdg1']
[2023-06-13T03:17:33.999+0000] {standard_task_runner.py:85} INFO - Job 42: Subtask creacion_tabla
[2023-06-13T03:17:34.069+0000] {task_command.py:410} INFO - Running <TaskInstance: vamosSigue.creacion_tabla scheduled__2023-06-12T00:00:00+00:00 [running]> on host a26553e1bb12
[2023-06-13T03:17:34.192+0000] {taskinstance.py:1547} INFO - Exporting env vars: AIRFLOW_CTX_DAG_OWNER='***' AIRFLOW_CTX_DAG_ID='vamosSigue' AIRFLOW_CTX_TASK_ID='creacion_tabla' AIRFLOW_CTX_EXECUTION_DATE='2023-06-12T00:00:00+00:00' AIRFLOW_CTX_TRY_NUMBER='1' AIRFLOW_CTX_DAG_RUN_ID='scheduled__2023-06-12T00:00:00+00:00'
[2023-06-13T03:17:34.193+0000] {sql.py:262} INFO - Executing: 
            CREATE TABLE IF NOT EXISTS datos (
            id VARCHAR NOT NULL,
            country VARCHAR NOT NULL,
            );
          
[2023-06-13T03:17:34.220+0000] {taskinstance.py:1824} ERROR - Task failed with exception
Traceback (most recent call last):
  File "/home/airflow/.local/lib/python3.7/site-packages/airflow/providers/common/sql/operators/sql.py", line 263, in execute
    hook = self.get_db_hook()
  File "/home/airflow/.local/lib/python3.7/site-packages/airflow/providers/common/sql/operators/sql.py", line 181, in get_db_hook
    return self._hook
  File "/home/airflow/.local/lib/python3.7/site-packages/cached_property.py", line 36, in __get__
    value = obj.__dict__[self.func.__name__] = self.func(obj)
  File "/home/airflow/.local/lib/python3.7/site-packages/airflow/providers/common/sql/operators/sql.py", line 143, in _hook
    conn = BaseHook.get_connection(self.conn_id)
  File "/home/airflow/.local/lib/python3.7/site-packages/airflow/hooks/base.py", line 72, in get_connection
    conn = Connection.get_connection_from_secrets(conn_id)
  File "/home/airflow/.local/lib/python3.7/site-packages/airflow/models/connection.py", line 434, in get_connection_from_secrets
    raise AirflowNotFoundException(f"The conn_id `{conn_id}` isn't defined")
airflow.exceptions.AirflowNotFoundException: The conn_id `postgres_default` isn't defined
[2023-06-13T03:17:34.226+0000] {taskinstance.py:1350} INFO - Marking task as FAILED. dag_id=vamosSigue, task_id=creacion_tabla, execution_date=20230612T000000, start_date=20230613T031733, end_date=20230613T031734
[2023-06-13T03:17:34.246+0000] {standard_task_runner.py:109} ERROR - Failed to execute job 42 for task creacion_tabla (The conn_id `postgres_default` isn't defined; 473)
[2023-06-13T03:17:34.292+0000] {local_task_job_runner.py:225} INFO - Task exited with return code 1
[2023-06-13T03:17:34.331+0000] {taskinstance.py:2651} INFO - 0 downstream tasks scheduled from follow-on schedule check
